<?xml version="1.0" ?>
<!-- =================================================================================== -->
<!-- |    This document was autogenerated by xacro from vtec_u3.xacro                  | -->
<!-- |    EDITING THIS FILE BY HAND IS NOT RECOMMENDED                                 | -->
<!-- =================================================================================== -->
<robot name="vtec_u3">
  <include filename="/ws/src/vanttec_uv_sim/sensors/realsense_gazebo_plugin/models/realsense_camera/model.sdf"/>
  <!--
    Note: mimic tags should be checked if open/close operation of the gripper is desired
-->
  <virtual_joint child_link="vtec_u3_base_link" name="world_joint" parent_frame="world_ned" type="planar"/>
  <link name="vtec_u3_base_link">
    <inertial>
      <mass value="18.74"/>
      <origin rpy="0 0 0" xyz="0 0 0"/>
      <!-- From Pedro's report -->
      <!-- <inertia ixx="0.49770495" ixy="0.00275177" ixz="-0.0574426"
                   iyy="0.37089716" iyz="-0.0036791"
                   izz="0.64879823" /> -->
      <!-- For COM nearly in geometric center -->
      <inertia ixx="0.83639798529" ixy="-0.00503680373" ixz="0.0560001532" iyy="0.46118483068" iyz="-0.01377965358" izz="1.02986207702"/>
    </inertial>
    <visual>
      <origin rpy="0 0 0" xyz="-0.0069 -0.00909 -0.01005"/>
      <geometry>
        <mesh filename="file:///ws/src/vanttec_uv_sim/vehicle_descriptions/meshes/vtec_u3.dae" scale="0.001 0.001 0.001"/>
      </geometry>
    </visual>
    <!-- <collision>
          <origin xyz="0 0 0" rpy="0 0 0"/>
          <geometry>
            <mesh filename="${collision_mesh_file}" scale="0.001 0.001 0.001" />
          </geometry>
        </collision> -->
  </link>
  <gazebo reference="vtec_u3_base_link">
    <selfCollide>0</selfCollide>
    <turnGravityOff>1</turnGravityOff>
    <!-- CUSTOM PLUG-IN -->
    <!-- <plugin name="sixDOFMov" filename="libsixDOFMov.so">
        <commandTopic>/uuv_desired_velocity</commandTopic>
        <odometryTopic>odom</odometryTopic>
        <odometryFrame>odom</odometryFrame>
        <odometryRate>100.0</odometryRate>
        <robotBaseFrame>${namespace}_base_link</robotBaseFrame>
        <publishTF>false</publishTF>
      </plugin> -->
  </gazebo>
  <!-- Mount a Pose 3D sensor. -->
  <!--<xacro:default_pose_3d namespace="${namespace}" parent_link="${namespace}_base_link" /> -->
  <!-- Forward-looking sonar sensor -->
  <!--<xacro:forward_multibeam_p900 namespace="${namespace}" parent_link="${namespace}_base_link">
      <origin xyz="0 0 0" rpy="0 0 0"/> -->
  <!--</xacro:forward_multibeam_p900> -->
  <!-- DVL  -->
  <!--<xacro:default_dvl namespace="${namespace}" parent_link="${namespace}_base_link">
      <origin xyz="0 0 0" rpy="0 0 0"/>-->
  <!--</xacro:default_dvl> -->
  <!-- RPT  -->
  <!--<xacro:default_rpt namespace="${namespace}" parent_link="${namespace}_base_link">
      <origin xyz="0 0 0" rpy="0 0 0"/>-->
  <!--</xacro:default_rpt>-->
  <link name="vtec_u3/pressure_link">
    <inertial>
      <inertia ixx="0.00001" ixy="0.0" ixz="0.0" iyy="0.00001" iyz="0.0" izz="0.00001"/>
      <mass value="0.015"/>
      <!-- [kg] -->
      <origin rpy="0 0 0" xyz="0 0 0"/>
    </inertial>
    <visual>
      <geometry>
        <mesh filename="file:///ws/src/vanttec_uv_sim/sensors/uuv_sensor_plugins/uuv_sensor_ros_plugins/meshes/pressure.dae" scale="1 1 1"/>
      </geometry>
    </visual>
    <collision>
      <geometry>
        <cylinder length="1e-06" radius="1e-06"/>
      </geometry>
      <origin rpy="0 1.5707963267948966 0" xyz="0 0 0"/>
    </collision>
  </link>
  <joint name="vtec_u3/pressure_joint" type="revolute">
    <origin rpy="0 0 0" xyz="-0.10278 0.03138 0.10095"/>
    <parent link="vtec_u3_base_link"/>
    <child link="vtec_u3/pressure_link"/>
    <limit effort="0" lower="0" upper="0" velocity="0"/>
    <axis xyz="1 0 0"/>
  </joint>
  <gazebo>
    <plugin filename="libuuv_gazebo_ros_subsea_pressure_plugin.so" name="libuuv_gazebo_subseapressure_plugin">
      <robot_namespace>vtec_u3</robot_namespace>
      <!-- (string, required): ros namespace in which the messages are published -->
      <link_name>vtec_u3/pressure_link</link_name>
      <!-- (string, required): name of the body which holds the IMU sensor -->
      <sensor_topic>pressure</sensor_topic>
      <!-- (string): name of the sensor output topic and prefix of service names (defaults to imu) -->
      <update_rate>10</update_rate>
      <!-- Update period of accelerometer and gyroscope [s] -->
      <saturation>30000</saturation>
      <!-- measurement range [kPa] -->
      <noise_sigma>3.0</noise_sigma>
      <!-- measurement stddev [kPa] -->
      <noise_amplitude>0.0</noise_amplitude>
      <estimate_depth_on>False</estimate_depth_on>
      <!-- infer depth? -->
      <standard_pressure>101.325</standard_pressure>
      <!-- pressure at sea level (depth 0 m) [kPa] -->
      <kPa_per_meter>9.80638</kPa_per_meter>
      <!-- increase in pressure [kPa] per [m] in increased depth -->
      <enable_gazebo_messages>false</enable_gazebo_messages>
    </plugin>
  </gazebo>
  <!-- IMU link -->
  <link name="vtec_u3/imu_link">
    <inertial>
      <inertia ixx="0.00001" ixy="0.0" ixz="0.0" iyy="0.00001" iyz="0.0" izz="0.00001"/>
      <mass value="0.015"/>
      <!-- [kg] -->
      <origin rpy="0 0 0" xyz="0 0 0"/>
    </inertial>
  </link>
  <!-- IMU joint -->
  <joint name="vtec_u3/imu_joint" type="revolute">
    <origin rpy="0 0 0" xyz="0.08992 0.00853 0.05671"/>
    <parent link="vtec_u3_base_link"/>
    <child link="vtec_u3/imu_link"/>
    <limit effort="0" lower="0" upper="0" velocity="0"/>
    <axis xyz="1 0 0"/>
  </joint>
  <gazebo>
    <plugin filename="libuuv_gazebo_ros_imu_plugin.so" name="libuuv_gazebo_imu_plugin">
      <!-- A good description of the IMU parameters can be found in the kalibr documentation:
           https://github.com/ethz-asl/kalibr/wiki/IMU-Noise-Model-and-Intrinsics -->
      <robot_namespace>vtec_u3</robot_namespace>
      <!-- (string, required): ros namespace in which the messages are published -->
      <link_name>vtec_u3/imu_link</link_name>
      <!-- (string, required): name of the body which holds the IMU sensor -->
      <sensor_topic>imu</sensor_topic>
      <!-- (string): name of the sensor output topic and prefix of service names (defaults to imu) -->
      <gyroscope_noise_density>0.0003394</gyroscope_noise_density>
      <!-- Gyroscope noise density (two-sided spectrum) [rad/s/sqrt(Hz)] -->
      <gyroscope_random_walk>3.8785e-05</gyroscope_random_walk>
      <!-- Gyroscope bias random walk [rad/s/s/sqrt(Hz)] -->
      <gyroscope_bias_correlation_time>1000.0</gyroscope_bias_correlation_time>
      <!-- Gyroscope bias correlation time constant [s] -->
      <gyroscope_turn_on_bias_sigma>0.0087</gyroscope_turn_on_bias_sigma>
      <!-- Gyroscope turn on bias standard deviation [rad/s] -->
      <accelerometer_noise_density>0.004</accelerometer_noise_density>
      <!-- Accelerometer noise density (two-sided spectrum) [m/s^2/sqrt(Hz)] -->
      <accelerometer_random_walk>0.006</accelerometer_random_walk>
      <!-- Accelerometer bias random walk. [m/s^2/s/sqrt(Hz)] -->
      <accelerometer_bias_correlation_time>300.0</accelerometer_bias_correlation_time>
      <!-- Accelerometer bias correlation time constant [s] -->
      <accelerometer_turn_on_bias_sigma>0.196</accelerometer_turn_on_bias_sigma>
      <!-- Accelerometer turn on bias standard deviation [m/s^2] -->
      <orientation_noise>0.01</orientation_noise>
      <update_rate>50</update_rate>
      <!-- Update period of accelerometer and gyroscope [s] -->
      <enable_gazebo_messages>false</enable_gazebo_messages>
      <enable_local_ned_frame>False</enable_local_ned_frame>
      <static_reference_frame>world</static_reference_frame>
    </plugin>
  </gazebo>
  <!-- Camera link -->
  <link name="frontrs200_camera">
    <visual>
      <origin rpy="0 0 0" xyz="0 0 0"/>
      <geometry>
        <mesh filename="package://realsense_gazebo_plugin/models/realsense_camera/meshes/realsense.dae"/>
      </geometry>
    </visual>
    <collision>
      <geometry>
        <box size="0.0078 0.130 0.0192"/>
      </geometry>
    </collision>
    <inertial>
      <mass value="0.0615752"/>
      <origin rpy="0 0 0" xyz="0 0 0"/>
      <inertia ixx="9.108e-05" ixy="0" ixz="0" iyy="2.51e-06" iyz="0" izz="8.931e-05"/>
    </inertial>
  </link>
  <!-- Connect camera to parent frame-->
  <joint name="frontrealsense_joint" type="fixed">
    <parent link="vtec_u3_base_link"/>
    <child link="frontrs200_camera"/>
    <origin rpy="0 0 0" xyz="0.19281 0.01961 0.06659"/>
  </joint>
  <!-- Virtual links representing the cameras positons and orientations-->
  <link name="frontcolor"/>
  <link name="frontdepth"/>
  <link name="frontired1"/>
  <link name="frontired2"/>
  <!-- Joints positioning the virtual links with respect to the camera main link-->
  <joint name="frontcolor_joint" type="fixed">
    <parent link="frontrs200_camera"/>
    <child link="frontcolor"/>
    <!-- <origin xyz="0 -0.046 0.004" rpy="0 0 0"/> -->
    <!-- The default position is change since in Rviz the cloud depth axis is Z not X-->
    <origin rpy="1.5707963267948966 3.141592653589793 1.5707963267948966" xyz="0 -0.046 0.004"/>
  </joint>
  <joint name="frontdepth_joint" type="fixed">
    <parent link="frontrs200_camera"/>
    <child link="frontdepth"/>
    <origin rpy="0 0 0" xyz="0 -0.03 0.004"/>
  </joint>
  <joint name="frontired1_joint" type="fixed">
    <parent link="frontrs200_camera"/>
    <child link="frontired1"/>
    <origin rpy="0 0 0" xyz="0 -0.06 0.004"/>
  </joint>
  <joint name="frontired2_joint" type="fixed">
    <parent link="frontrs200_camera"/>
    <child link="frontired2"/>
    <origin rpy="0 0 0" xyz="0 0.01 0.004"/>
  </joint>
  <!-- **********************************************************-->
  <!-- GAZEBO DEFINITIONS ***************************************-->
  <!-- Load plugin to the model ("robot" in urdf format)-->
  <gazebo>
    <plugin filename="librealsense_gazebo_plugin.so" name="frontr200">
      <prefix>front</prefix>
    </plugin>
    <!--<pose frame="">0 0 0.015 0 0 0</pose>-->
  </gazebo>
  <!-- Load parameters to model's main link-->
  <gazebo reference="frontrs200_camera">
    <self_collide>0</self_collide>
    <enable_wind>0</enable_wind>
    <kinematic>0</kinematic>
    <turnGravityOff>1</turnGravityOff>
    <!-- <gravity>0</gravity> -->
    <!--<mu>1</mu>-->
    <mu2>1</mu2>
    <fdir1>0 0 0</fdir1>
    <!--<slip1>0</slip1>
        <slip2>0</slip2>-->
    <kp>1e+13</kp>
    <kd>1</kd>
    <!--<max_vel>0.01</max_vel>
        <min_depth>0</min_depth>-->
    <sensor name="frontcolor" type="camera">
      <pose frame="">0 -0.046 0.004 0 0 0</pose>
      <camera name="frontrs200_camera">
        <horizontal_fov>1.047</horizontal_fov>
        <image>
          <width>640</width>
          <height>480</height>
          <format>RGB_INT8</format>
        </image>
        <clip>
          <near>0.1</near>
          <far>100</far>
        </clip>
        <noise>
          <type>gaussian</type>
          <mean>0.0</mean>
          <stddev>0.007</stddev>
        </noise>
      </camera>
      <always_on>1</always_on>
      <update_rate>60</update_rate>
      <visualize>1</visualize>
    </sensor>
    <sensor name="frontired1" type="camera">
      <pose frame="">0 -0.06 0.004 0 0 0</pose>
      <camera name="frontrs200_camera">
        <horizontal_fov>1.047</horizontal_fov>
        <image>
          <width>640</width>
          <height>480</height>
          <format>L_INT8</format>
        </image>
        <clip>
          <near>0.1</near>
          <far>100</far>
        </clip>
        <noise>
          <type>gaussian</type>
          <mean>0.0</mean>
          <stddev>0.05</stddev>
        </noise>
      </camera>
      <always_on>1</always_on>
      <update_rate>60</update_rate>
      <visualize>0</visualize>
    </sensor>
    <sensor name="frontired2" type="camera">
      <pose frame="">0 0.01 0.004 0 0 0</pose>
      <camera name="frontrs200_camera">
        <horizontal_fov>1.047</horizontal_fov>
        <image>
          <width>640</width>
          <height>480</height>
          <format>L_INT8</format>
        </image>
        <clip>
          <near>0.1</near>
          <far>100</far>
        </clip>
        <noise>
          <type>gaussian</type>
          <mean>0.0</mean>
          <stddev>0.05</stddev>
        </noise>
      </camera>
      <always_on>1</always_on>
      <update_rate>60</update_rate>
      <visualize>0</visualize>
    </sensor>
    <sensor name="frontdepth" type="depth">
      <pose frame="">0 -0.03 0.004 0 0 0</pose>
      <camera name="frontrs200_camera">
        <horizontal_fov>1.047</horizontal_fov>
        <image>
          <width>640</width>
          <height>480</height>
        </image>
        <clip>
          <near>0.1</near>
          <far>100</far>
        </clip>
        <noise>
          <type>gaussian</type>
          <mean>0.0</mean>
          <stddev>0.100</stddev>
        </noise>
      </camera>
      <always_on>1</always_on>
      <update_rate>60</update_rate>
      <visualize>0</visualize>
    </sensor>
  </gazebo>
  <!-- Camera link -->
  <link name="downrs200_camera">
    <visual>
      <origin rpy="0 0 0" xyz="0 0 0"/>
      <geometry>
        <mesh filename="package://realsense_gazebo_plugin/models/realsense_camera/meshes/realsense.dae"/>
      </geometry>
    </visual>
    <collision>
      <geometry>
        <box size="0.0078 0.130 0.0192"/>
      </geometry>
    </collision>
    <inertial>
      <mass value="0.0615752"/>
      <origin rpy="0 0 0" xyz="0 0 0"/>
      <inertia ixx="9.108e-05" ixy="0" ixz="0" iyy="2.51e-06" iyz="0" izz="8.931e-05"/>
    </inertial>
  </link>
  <!-- Connect camera to parent frame-->
  <joint name="downrealsense_joint" type="fixed">
    <parent link="vtec_u3_base_link"/>
    <child link="downrs200_camera"/>
    <origin rpy="0 1.57 0" xyz="0.0 0.01961 0.18"/>
  </joint>
  <!-- Virtual links representing the cameras positons and orientations-->
  <link name="downcolor"/>
  <link name="downdepth"/>
  <link name="downired1"/>
  <link name="downired2"/>
  <!-- Joints positioning the virtual links with respect to the camera main link-->
  <joint name="downcolor_joint" type="fixed">
    <parent link="downrs200_camera"/>
    <child link="downcolor"/>
    <!-- <origin xyz="0 -0.046 0.004" rpy="0 0 0"/> -->
    <!-- The default position is change since in Rviz the cloud depth axis is Z not X-->
    <origin rpy="1.5707963267948966 3.141592653589793 1.5707963267948966" xyz="0 -0.046 0.004"/>
  </joint>
  <joint name="downdepth_joint" type="fixed">
    <parent link="downrs200_camera"/>
    <child link="downdepth"/>
    <origin rpy="0 0 0" xyz="0 -0.03 0.004"/>
  </joint>
  <joint name="downired1_joint" type="fixed">
    <parent link="downrs200_camera"/>
    <child link="downired1"/>
    <origin rpy="0 0 0" xyz="0 -0.06 0.004"/>
  </joint>
  <joint name="downired2_joint" type="fixed">
    <parent link="downrs200_camera"/>
    <child link="downired2"/>
    <origin rpy="0 0 0" xyz="0 0.01 0.004"/>
  </joint>
  <!-- **********************************************************-->
  <!-- GAZEBO DEFINITIONS ***************************************-->
  <!-- Load plugin to the model ("robot" in urdf format)-->
  <gazebo>
    <plugin filename="librealsense_gazebo_plugin.so" name="downr200">
      <prefix>down</prefix>
    </plugin>
    <!--<pose frame="">0 0 0.015 0 0 0</pose>-->
  </gazebo>
  <!-- Load parameters to model's main link-->
  <gazebo reference="downrs200_camera">
    <self_collide>0</self_collide>
    <enable_wind>0</enable_wind>
    <kinematic>0</kinematic>
    <turnGravityOff>1</turnGravityOff>
    <!-- <gravity>0</gravity> -->
    <!--<mu>1</mu>-->
    <mu2>1</mu2>
    <fdir1>0 0 0</fdir1>
    <!--<slip1>0</slip1>
        <slip2>0</slip2>-->
    <kp>1e+13</kp>
    <kd>1</kd>
    <!--<max_vel>0.01</max_vel>
        <min_depth>0</min_depth>-->
    <sensor name="downcolor" type="camera">
      <pose frame="">0 -0.046 0.004 0 0 0</pose>
      <camera name="downrs200_camera">
        <horizontal_fov>1.047</horizontal_fov>
        <image>
          <width>640</width>
          <height>480</height>
          <format>RGB_INT8</format>
        </image>
        <clip>
          <near>0.1</near>
          <far>100</far>
        </clip>
        <noise>
          <type>gaussian</type>
          <mean>0.0</mean>
          <stddev>0.007</stddev>
        </noise>
      </camera>
      <always_on>1</always_on>
      <update_rate>60</update_rate>
      <visualize>1</visualize>
    </sensor>
    <sensor name="downired1" type="camera">
      <pose frame="">0 -0.06 0.004 0 0 0</pose>
      <camera name="downrs200_camera">
        <horizontal_fov>1.047</horizontal_fov>
        <image>
          <width>640</width>
          <height>480</height>
          <format>L_INT8</format>
        </image>
        <clip>
          <near>0.1</near>
          <far>100</far>
        </clip>
        <noise>
          <type>gaussian</type>
          <mean>0.0</mean>
          <stddev>0.05</stddev>
        </noise>
      </camera>
      <always_on>1</always_on>
      <update_rate>60</update_rate>
      <visualize>0</visualize>
    </sensor>
    <sensor name="downired2" type="camera">
      <pose frame="">0 0.01 0.004 0 0 0</pose>
      <camera name="downrs200_camera">
        <horizontal_fov>1.047</horizontal_fov>
        <image>
          <width>640</width>
          <height>480</height>
          <format>L_INT8</format>
        </image>
        <clip>
          <near>0.1</near>
          <far>100</far>
        </clip>
        <noise>
          <type>gaussian</type>
          <mean>0.0</mean>
          <stddev>0.05</stddev>
        </noise>
      </camera>
      <always_on>1</always_on>
      <update_rate>60</update_rate>
      <visualize>0</visualize>
    </sensor>
    <sensor name="downdepth" type="depth">
      <pose frame="">0 -0.03 0.004 0 0 0</pose>
      <camera name="downrs200_camera">
        <horizontal_fov>1.047</horizontal_fov>
        <image>
          <width>640</width>
          <height>480</height>
        </image>
        <clip>
          <near>0.1</near>
          <far>100</far>
        </clip>
        <noise>
          <type>gaussian</type>
          <mean>0.0</mean>
          <stddev>0.100</stddev>
        </noise>
      </camera>
      <always_on>1</always_on>
      <update_rate>60</update_rate>
      <visualize>0</visualize>
    </sensor>
  </gazebo>
  <!-- Realsense R200 -->
  <!-- Import macro for realsense-RS200 camera-->
  <!-- <xacro:include filename="$(find realsense_gazebo_plugin)/urdf/realsense-RS200.macro.xacro"/>-->
  <!-- Create camera instance -->
  <!--<xacro:realsense-rs200 prefix="" parent="${namespace}_base_link">-->
  <!--  <origin xyz="0.19281 0.01961 0.06659" rpy="0 0 0"/>-->
  <!--</xacro:realsense-rs200>-->
  <!-- Mount a camera  -->
  <!-- <xacro:default_camera namespace="${namespace}" parent_link="${namespace}_base_link" suffix="">
      <origin xyz="0.19281 0.01961 0.06659" rpy="0 0 0"/>
    </xacro:default_camera> -->
  <gazebo reference="arm_rail_link">
    <material>Gazebo/White</material>
    <turnGravityOff>1</turnGravityOff>
    <selfCollide>0</selfCollide>
  </gazebo>
  <gazebo reference="extendible_arm_link">
    <material>Gazebo/White</material>
    <turnGravityOff>1</turnGravityOff>
    <selfCollide>0</selfCollide>
  </gazebo>
  <gazebo reference="left_beam_link">
    <material>Gazebo/White</material>
    <turnGravityOff>1</turnGravityOff>
    <selfCollide>0</selfCollide>
  </gazebo>
  <gazebo reference="right_beam_link">
    <material>Gazebo/White</material>
    <turnGravityOff>1</turnGravityOff>
    <selfCollide>0</selfCollide>
  </gazebo>
  <gazebo reference="left_tip_link">
    <material>Gazebo/White</material>
    <turnGravityOff>1</turnGravityOff>
    <selfCollide>0</selfCollide>
    <!-- <kp>1000000.0</kp>
        <kd>1.5</kd>
        <mu1>1.5</mu1>
        <mu2>1.5</mu2>
        <minDepth>0.0001</minDepth> -->
  </gazebo>
  <gazebo reference="right_tip_link">
    <material>Gazebo/White</material>
    <turnGravityOff>1</turnGravityOff>
    <selfCollide>0</selfCollide>
    <!-- <kp>1000000.0</kp>
        <kd>1.5</kd>
        <mu1>1.5</mu1>
        <mu2>1.5</mu2>
        <minDepth>0.0001</minDepth> -->
  </gazebo>
  <joint name="vtec_u3_base_link_2_arm_rail_link_joint" type="fixed">
    <origin rpy="0 0 0" xyz="0 0 -0.17"/>
    <parent link="vtec_u3_base_link"/>
    <child link="arm_rail_link"/>
  </joint>
  <link name="arm_rail_link">
    <visual>
      <origin rpi="0 0 0" xyz="0 0 0"/>
      <geometry>
        <mesh filename="package://vehicle_descriptions/meshes/arm/arm_rail.stl"/>
      </geometry>
    </visual>
    <!-- Leave commented. This makes the whole arm to move -->
    <!-- <collision>
        <origin xyz="0 0 0" rpy="0 0 0" />
        <geometry>
          <mesh filename="package://vehicle_descriptions/meshes/arm/arm_rail.stl" />
        </geometry>
      </collision> -->
    <inertial>
      <origin rpy="0 0 0" xyz="-0.000143143841055618 0.0093355201368952 0.0425505188622381"/>
      <mass value="0.214808103264679"/>
      <inertia ixx="0.0001" ixy="0.0" ixz="0.0" iyy="0.0001" iyz="0.0" izz="0.0001"/>
    </inertial>
  </link>
  <joint name="arm_rail_link_2_extendible_arm_link_joint" type="prismatic">
    <axis xyz="0 0 1"/>
    <limit effort="1000.0" lower="-0.09" upper="0.12" velocity="0.001"/>
    <origin rpy="1.5708 0 1.5708" xyz="0.15257 -0.00014633 0.003"/>
    <parent link="arm_rail_link"/>
    <child link="extendible_arm_link"/>
  </joint>
  <link name="extendible_arm_link">
    <visual>
      <origin rpy="0 0 0" xyz="0 0 0"/>
      <geometry>
        <mesh filename="package://vehicle_descriptions/meshes/arm/extendible_arm.stl"/>
      </geometry>
    </visual>
    <!-- <collision>
        <origin xyz="0 0 0" rpy="0 0 0" />
        <geometry>
          <mesh filename="package://vehicle_descriptions/meshes/arm/extendible_arm.stl" />
        </geometry>
      </collision> -->
    <inertial>
      <origin rpy="0 0 0" xyz="0.00011792 0.019454 -0.085978"/>
      <mass value="0.14"/>
      <inertia ixx="0.0001" ixy="0.0" ixz="0.0" iyy="0.0001" iyz="0.0" izz="0.0001"/>
    </inertial>
  </link>
  <joint name="extendible_arm_link_2_left_beam_link_joint" type="revolute">
    <axis xyz="0 1 0"/>
    <limit effort="100" lower="0" upper="1" velocity="0.001"/>
    <origin rpy="0 -0.13439 0" xyz="0.025315 0.0212 0.078512"/>
    <parent link="extendible_arm_link"/>
    <child link="left_beam_link"/>
  </joint>
  <link name="left_beam_link">
    <visual>
      <origin rpy="0 0 0" xyz="0 0 0"/>
      <geometry>
        <mesh filename="package://vehicle_descriptions/meshes/arm/left_beam.stl"/>
      </geometry>
    </visual>
    <!-- <collision>
        <origin xyz="0 0 0" rpy="0 0 0" />
        <geometry>
          <mesh filename="package://vehicle_descriptions/meshes/arm/left_beam.stl" />
        </geometry>
      </collision> -->
    <inertial>
      <origin rpy="0 0 0" xyz="-0.0054587 -0.0045 0.020602"/>
      <mass value="0.0028443"/>
      <inertia ixx="0.0001" ixy="0.0" ixz="0.0" iyy="0.0001" iyz="0.0" izz="0.0001"/>
    </inertial>
  </link>
  <joint name="left_beam_link_2_left_tip_link_joint" type="revolute">
    <axis xyz="0 1 0"/>
    <limit effort="100" lower="-1" upper="0" velocity="0.001"/>
    <origin rpy="0 0.10761 0" xyz="0 -0.002 0.04"/>
    <parent link="left_beam_link"/>
    <child link="left_tip_link"/>
    <mimic joint="extendible_arm_link_2_left_beam_link" multiplier="-1" offset="0"/>
  </joint>
  <link name="left_tip_link">
    <visual>
      <origin rpy="0 0 0" xyz="0 0 0"/>
      <geometry>
        <mesh filename="package://vehicle_descriptions/meshes/arm/left_tip.stl"/>
      </geometry>
    </visual>
    <!-- <collision>
        <origin xyz="0 0 0" rpy="0 0 0" />
        <geometry>
          <mesh filename="package://vehicle_descriptions/meshes/arm/left_tip.stl" />
        </geometry>
      </collision> -->
    <inertial>
      <origin rpy="0 0 0" xyz="-0.010353 -0.0025 0.013922"/>
      <mass value="0.0028494"/>
      <inertia ixx="0.0001" ixy="0.0" ixz="0.0" iyy="0.0001" iyz="0.0" izz="0.0001"/>
    </inertial>
  </link>
  <joint name="extendible_arm_link_2_right_beam_link_joint" type="revolute">
    <axis xyz="0 1 0"/>
    <limit effort="100" lower="-1" upper="0" velocity="0.001"/>
    <origin rpy="0 0.13167 0" xyz="-0.025315 0.0212 0.078512"/>
    <parent link="extendible_arm_link"/>
    <child link="right_beam_link"/>
    <mimic joint="extendible_arm_link_2_left_beam_link" multiplier="-1" offset="0"/>
  </joint>
  <link name="right_beam_link">
    <visual>
      <origin rpy="0 0 0" xyz="0 0 0"/>
      <geometry>
        <mesh filename="package://vehicle_descriptions/meshes/arm/right_beam.stl"/>
      </geometry>
    </visual>
    <!-- <collision>
        <origin xyz="0 0 0" rpy="0 0 0" />
        <geometry>
          <mesh filename="package://vehicle_descriptions/meshes/arm/right_beam.stl" />
        </geometry>
      </collision> -->
    <inertial>
      <origin rpy="0 0 0" xyz="0.0054603 -0.0045 0.020616"/>
      <mass value="0.0028443"/>
      <inertia ixx="0.0001" ixy="0.0" ixz="0.0" iyy="0.0001" iyz="0.0" izz="0.0001"/>
    </inertial>
  </link>
  <joint name="right_beam_link_2_right_tip_link_joint" type="revolute">
    <axis xyz="0 1 0"/>
    <limit effort="100" lower="0" upper="1" velocity="0.001"/>
    <origin rpy="0 -0.10535 0" xyz="0 -0.002 0.04"/>
    <parent link="right_beam_link"/>
    <child link="right_tip_link"/>
    <mimic joint="extendible_arm_link_2_right_beam_link" multiplier="-1" offset="0"/>
  </joint>
  <link name="right_tip_link">
    <visual>
      <origin rpy="0 0 0" xyz="0 0 0"/>
      <geometry>
        <mesh filename="package://vehicle_descriptions/meshes/arm/right_tip.stl"/>
      </geometry>
    </visual>
    <!-- <collision>
        <origin xyz="0 0 0" rpy="0 0 0" />
        <geometry>
          <mesh filename="package://vehicle_descriptions/meshes/arm/right_tip.stl" />
        </geometry>
      </collision> -->
    <inertial>
      <origin rpy="0 0 0" xyz="0.010353 -0.0025 0.013922"/>
      <mass value="0.0028494"/>
      <inertia ixx="0.0001" ixy="0.0" ixz="0.0" iyy="0.0001" iyz="0.0" izz="0.0001"/>
    </inertial>
  </link>
  <!-- <xacro:property name="collision_mesh_file" value="file://$(find vehicle_descriptions)/meshes/shooter/shooter_base.dae"/> -->
  <gazebo reference="shooter_base_link">
    <material>Gazebo/White</material>
    <turnGravityOff>1</turnGravityOff>
    <selfCollide>0</selfCollide>
  </gazebo>
  <joint name="vtec_u3_base_link_2_shooter_base_joint" type="fixed">
    <origin rpy="0 0 -1.57079632679" xyz="0 0 0.2"/>
    <parent link="vtec_u3_base_link"/>
    <child link="shooter_base_link"/>
  </joint>
  <link name="shooter_base_link">
    <visual>
      <origin rpy="0.0 0.0 0.0" xyz="0.0 0.0 0.0"/>
      <geometry>
        <mesh filename="file:///ws/src/vanttec_uv_sim/vehicle_descriptions/meshes/shooter/shooter_base.dae" scale="0.001 0.001 0.001"/>
      </geometry>
    </visual>
    <!-- <collision>
          <origin xyz="0 0 0.0" rpy="0 0 0"/>
          <geometry>
            <box size="0.1 0.1 0.1"/>
            <mesh filename="${collision_mesh_file}" scale="0.001 0.001 0.001" />
          </geometry>
        </collision> -->
    <inertial>
      <origin rpy="0 0 0" xyz="0 0 0"/>
      <mass value="10"/>
      <inertia ixx="1.0" ixy="0.0" ixz="0.0" iyy="1.0" iyz="0.0" izz="1.0"/>
    </inertial>
  </link>
  <!-- Joint state publisher plugin -->
  <!-- <xacro:default_joint_state_publisher namespace="$(arg namespace)" update_rate="10"/> -->
</robot>

