<?xml version="1.0" ?>

<robot name="brazo"> xmlns:xacro="http://www.ros.org/wiki/xacro">
  <link name= "base_link">
    <visual>
      <origin rpi="0 0 0" xyz="0 0 0"/>
      <geometry>
        <mesh filename="package://brazo_assembly/meshes/base_link.STL" />
      </geometry>
    </visual>
    <collision>
      <origin xyz="0 0 0" rpy="0 0 0" />
      <geometry>
        <mesh filename="package://brazo_assembly/meshes/base_link.STL" />
      </geometry>
    </collision>
    <inertial>
      <origin xyz="0. 0.0093355201368952 0.0425505188622381" rpy="0 0 0" />
      <mass value="0.3050" />
      <inertia ixx="63.4923" ixy="-0.4968" ixz="4.1743" iyy="62.6856" iyz="-7.5987" izz="3.7241" />
    </inertial>
  </link>

  <joint name="base_link__Link_brazo" type="prismatic">
    <axis xyz="0 0 1" />
    <limit effort="1000.0" lower="-0.09" upper="0.12" velocity="0.001" />
    <origin xyz="0.15257 -0.00014633 0.003" rpy="1.5708 0 1.5708" />
    <parent link="base_link" />
    <child link="Link_brazo" />
  </joint>

  <link name ="Link_brazo">
    <visual>
      <origin xyz="0 0 0" rpy="0 0 0" />
      <geometry>
        <mesh filename="package://brazo_assembly/meshes/Link_brazo.STL" />
      </geometry>
    </visual>
    <collision>
      <origin xyz="0 0 0" rpy="0 0 0" />
      <geometry>
        <mesh filename="package://brazo_assembly/meshes/Link_brazo.STL" />
      </geometry>
    </collision>
  </link>

  <link name="Link_viga_izquierda">
    <visual>
      <origin xyz="0 0 0" rpy="0 0 0" />
      <geometry>
        <mesh filename="package://brazo_assembly/meshes/Link_viga_izquierda.STL" />
      </geometry>
    </visual>
    <collision>
      <origin xyz="0 0 0" rpy="0 0 0" />
      <geometry>
        <mesh filename="package://brazo_assembly/meshes/Link_viga_izquierda.STL" />
      </geometry>
    </collision>
  </link>

  <joint name="Link_brazo__Link_viga_izquierda" type="revolute">
    <axis xyz="0 1 0" />
    <limit lower="0" upper="1" effort="100" velocity="0.001" />
    <origin xyz="0.025315 0.0212 0.078512" rpy="0 -0.13439 0" />
    <child link="Link_viga_izquierda" />
    <parent link="Link_brazo" />
  </joint>

  <link name="Link_punta_izquierda">
    <visual>
      <origin xyz="0 0 0" rpy="0 0 0" />
      <geometry>
        <mesh filename="package://brazo_assembly/meshes/Link_punta_izquierda.STL" />
      </geometry>
    </visual>
    <collision>
      <origin xyz="0 0 0" rpy="0 0 0" />
      <geometry>
        <mesh filename="package://brazo_assembly/meshes/Link_punta_izquierda.STL" />
      </geometry>
    </collision>
  </link>

  <joint name="Link_viga_izquierda__Link_punta_izquierda" type="revolute">
    <axis xyz="0 1 0" />
    <limit lower="-1" upper="0" effort="100" velocity="0.001" />
    <origin xyz="0 -0.002 0.04" rpy="0 0.10761 0" />
    <child link="Link_punta_izquierda" />
    <parent link="Link_viga_izquierda" />
    <mimic joint="Link_brazo__Link_viga_izquierda" multiplier="-1" offset="0" />
  </joint>

  <link name="Link_viga_derecha">
    <visual>
      <origin xyz="0 0 0" rpy="0 0 0" />
      <geometry>
        <mesh filename="package://brazo_assembly/meshes/Link_viga_derecha.STL" />
      </geometry>
    </visual>
    <collision>
      <origin xyz="0 0 0" rpy="0 0 0" />
      <geometry>
        <mesh filename="package://brazo_assembly/meshes/Link_viga_derecha.STL" />
      </geometry>
    </collision>
  </link>
  <joint name="Link_brazo__Link_viga_derecha" type="revolute">
    <axis xyz="0 1 0" />
    <limit lower="-1" upper="0" effort="100" velocity="0.001" />
    <origin xyz="-0.025315 0.0212 0.078512" rpy="0 0.13167 0" />
    <child link="Link_viga_derecha" />
    <parent link="Link_brazo" />
    <mimic joint="Link_brazo__Link_viga_izquierda" multiplier="-1" offset="0" />
  </joint>

  <link name="Link_punta_derecha">
    <visual>
      <origin xyz="0 0 0" rpy="0 0 0" />
      <geometry>
        <mesh filename="package://brazo_assembly/meshes/Link_punta_derecha.STL" />
      </geometry>
    </visual>
    <collision>
      <origin xyz="0 0 0" rpy="0 0 0" />
      <geometry>
        <mesh filename="package://brazo_assembly/meshes/Link_punta_derecha.STL" />
      </geometry>
    </collision>
  </link>

  <joint name="Link_viga_derecha__Link_punta_derecha" type="revolute">
    <axis xyz="0 1 0" />
    <limit lower="0" upper="1" effort="100" velocity="0.001" />
    <origin xyz="0 -0.002 0.04" rpy="0 -0.10535 0" />
    <child link="Link_punta_derecha" />
    <parent link="Link_viga_derecha" />
    <mimic joint="Link_brazo__Link_viga_derecha" multiplier="-1" offset="0" />
  </joint>
</robot>
